Workbook

Sheet request
A1: version | B1: entries for deprecation changes | C1: section | D1: keyword
A2: 0.6.6 | B2: -
A3: 0.10.1 | B3: -
A4: 2.16.5 | B4: -
A5: 2.20.1 | B5: -
A6: 2.26.0 | B6: -

Sheet numpy
A1: version | B1: entries for deprecation changes | C1: section | D1: keyword
A2: 1.13.3 | B2: -
A3: 1.16.5 | B3: -
A4: 1.16.6 | B4: -
A5: 1.12.1 | B5: -
A6: total= | B6: 0

Sheet pandas
A1: version | B1: entries for deprecation changes | C1: section | D1: keyword
A2: 0.7.1 | B2: -
A3: 0.8.0 | B3: New DatetimeIndex class supports both fixed frequency and irregular time series. Replaces now deprecated DateRange class | C3: Time Series changes and improvements | D3: replaces, deprecated
A4: 0.8.0 | B4: Rename Factor to Categorical and add a number of usability features | C4: Other new features | D4: rename
A5: 0.8.0 | B5: DateRange has been replaced by DatetimeIndex but otherwise behaved identically. | C5: Potential porting issues for pandas <= 0.7.3 users | D5: replaced
A6: 0.10.0 | B6: -
A7: 0.25.1 | B7: -
A8: 1.0.0 | B8: As part of a larger refactor to MultiIndex the level names are now stored separately from the levels (GH 27242). We recommend using MultiIndex.names to access the names, and Index.set_names() to update the names. For backwards compatibility, you can still access the names via the levels.However, it is no longer possible to update the names of the MultiIndex via the level. | C8: Backwards incompatible API changes | D8: recommend, no longer possible
A9: 1.0.0 | B9: Series.str.__iter__() was deprecated and will be removed in future releases | C9: Backwards incompatible API changes | D9: deprecated, removed
A10: 1.0.0 | B10: Index.set_value has been deprecated. For a given index idx, array arr, value in idx of idx_val and a new value of val, idx.set_value(arr, idx_val, val) is equivalent to arr[idx.get_loc(idx_val)] = val, which should be used instead | C10: Deprecations | D10: deprecated, instead
A11: 1.0.0 | B11: is_extension_type() is deprecated, is_extension_array_dtype() should be used instead | C11: Deprecations | D11: deprecated, instead
A12: 1.0.0 | B12: DateOffset.isAnchored() and DatetOffset.onOffset() are deprecated and will be removed in a future version, use DateOffset.is_anchored() and DateOffset.is_on_offset() instead | C12: Deprecations | D12: deprecated, removed, instead
A13: 1.0.0 | B13: pandas.tseries.frequencies.get_offset is deprecated and will be removed in a future version, use pandas.tseries.frequencies.to_offset instead | C13: Deprecations | D13: deprecated, removed, instead
A14: 1.0.0 | B14: Categorical.take_nd() and CategoricalIndex.take_nd() are deprecated, use Categorical.take() and CategoricalIndex.take() instead | C14: Deprecations | D14: deprecated, instead
A15: 1.0.0 | B15: pandas.core.index has been deprecated and will be removed in a future version, the public classes are available in the top-level namespace | C15: Deprecations | D15: deprecated, removed
A16: 1.0.0 | B16: pandas.json_normalize() is now exposed in the top-level namespace. Usage of json_normalize as pandas.io.json.json_normalize is now deprecated and it is recommended to use json_normalize as pandas.json_normalize() instead | C16: Deprecations | D16: deprecated, recommended, instead
A17: 1.0.0 | B17: The pandas.util.testing module has been deprecated. Use the public API in pandas.testing documented at Assertion functions | C17: Deprecations | D17: deprecated
A18: 1.0.0 | B18: pandas.SparseArray has been deprecated. Use pandas.arrays.SparseArray (arrays.SparseArray) instead. | C18: Deprecations | D18: deprecated, instead
A19: 1.0.0 | B19: The pandas.np submodule is now deprecated. Import numpy directly instead | C19: Deprecations | D19: deprecated, instead
... A64: 1.0.0 | B64: Removed Series.compress | C64: Removal of prior version deprecations/changes | D64: removed
A65: total= | B65: 60

Sheet click
A1: version | B1: entries for deprecation changes | C1: section | D1: keyword
A2: 2.4 | B2: -
A3: 2.5 | B3: -
A4: 4.0 | B4: -
A5: 7.0 | B5: -
A6: 7.1.1 | B6: -
A7: total= | B7: 0

Sheet flask
A1: version | B1: entries for deprecation changes | C1: section | D1: keyword
A2: 0.2 | B2: -
A3: 0.3.1 | B3: -
A4: 1.1.1 | B4: The flask.json_available flag was added back for compatibility with some extensions. It will raise a deprecation warning when used, and will be removed in version 2.0.0. | D4: deprecation, removed
A5: 1.1.4 | B5: -
A6: 2.0.3 | B6: -
A7: total= | B7: 1

Sheet pydantic
A1: version | B1: entries for deprecation changes | C1: section | D1: keyword
A2: 0.6.0 | B2: depreciate values(...) and replace with .dict(...) | D2: deprecate
A3: 0.11.0 | B3: breaking change: remove msgpack parsing | D3: remove
A4: 0.32 | B4: breaking change: remove __getattr__ and rename __values__ to __dict__ on BaseModel, deprecation warning on use __values__ attr, attributes access speed increased up to 14 times | D4: remove, rename, deprecation
A5: 0.32.1 | B5: -
A6: 1.5.1 | B6: -
A7: total | B7: 3

Sheet SciPy
A1: version | B1: entries for deprecation changes | C1: section | D1: keyword
A2: 0.8.0 | B2: The modules helpmod, ppimport and pexec from scipy.misc are deprecated. They will be removed from SciPy in version 0.9. | C2: Deprecated features | D2: deprecated, removed
A3: 0.8.0 | B3: Passing the coefficients of a polynomial as the argument f0 to signal.chirp is deprecated. Use the function signal.sweep_poly instead. | C3: Deprecated features | D3: deprecated, instead
A4: 0.8.0 | B4: The io.recaster module has been deprecated and will be removed in 0.9.0. | C4: Deprecated features | D4: deprecated, removed
A5: 0.8.0 | B5: scipy.stsci: the package was removed | C5: Removed features | D5: removed
A6: 0.8.0 | B6: The module scipy.misc.limits was removed. | C6: Removed features | D6: removed
A7: 0.8.0 | B7: Several functions in scipy.io are removed in the 0.8.0 release including: npfile, save, load, create_module, create_shelf, objload, objsave, fopen, read_array, write_array, fread, fwrite, bswap, packbits, unpackbits, and convert_objectarray. Some of these functions have been replaced by NumPy’s raw reading and writing capabilities, memory-mapping capabilities, or array methods. Others have been moved from SciPy to NumPy, since basic array reading and writing capability is now handled by NumPy. | C7: Removed features | D7: removed, replaced, moved
A8: 1.6.2 | B8: -
A9: 1.7.3 | B9: -
A10: 1.10.1 | B10: -
A11: 1.13.1 | B11: -
A12: total= | B12: 6

Sheet pillow
A1: version | B1: entries for deprecation changes | C1: section | D1: keyword
A2: 3.1.0 | B2: -
A3: 3.3.2 | B3: -
A4: 3.4.0 | B4: The nominally private/debugging function Image.core.open_ppm has been removed. If you were using this function, please use Image.open instead. | C4: Backwards Incompatible Changes | D4: removed, instead
A5: 7.1.2 | B5: -
A6: 8.1.0 | B6: -
A7: total= | B7: 1

Sheet scikit-learn
A1: version | B1: entries for deprecation changes | C1: section | D1: keyword
A2: 0.8 | B2: -
A3: 0.15.1 | B3: -
A4: 0.15.2 | B4: -
A5: 0.16.1 | B5: -
A6: 0.21.0 | B6: ensemble.partial_dependence and ensemble.plot_partial_dependence are now deprecated in favor of inspection.partial_dependence and inspection.plot_partial_dependence<sklearn.inspection.plot_partial_dependence>. | C6: Changlog | D6: deprecated, in favor of
A7: 0.21.0 | B7: linear_model.logistic_regression_path is deprecated in version 0.21 and will be removed in version 0.23. | C7: Changlog | D7: deprecated, removed
A8: 0.21.0 | B8: metrics.jaccard_similarity_score is deprecated in favour of the more consistent metrics.jaccard_score. The former behavior for binary and multiclass targets is broken. #13151 by Joel Nothman. | C8: Changlog | D8: deprecated, in favour of
A9: total= | B9: 3

Sheet matplotlib
A1: version | B1: entries for deprecation changes | C1: section | D1: keyword
A2: 0.99 | B2: pylab no longer provides a load and save function. These are available in matplotlib.mlab, or you can use numpy.loadtxt and numpy.savetxt for text files, or np.save and np.load for binary NumPy arrays. | C2: Changes in 0.99 | D2: no longer provides
A3: 0.99 | B3: There is a new rc parameter axes.color_cycle, and the color cycle is now independent of the rc parameter lines.color. matplotlib.Axes.set_default_color_cycle is deprecated. | C3: Changes beyond 0.99.x | D3: deprecated
A4: 2.2 | B4: The unused and untested Artist.onRemove and Artist.hitlist methods have been deprecated. | C4: Deprecations | D4: deprecated
A5: 2.2 | B5: The now unused mlab.less_simple_linear_interpolation function is deprecated. | C5: Deprecations | D5: deprecated
A6: 2.2 | B6: The unused ContourLabeler.get_real_label_width method is deprecated. | C6: Deprecations | D6: deprecated
A7: 2.2 | B7: The unused FigureManagerBase.show_popup method is deprecated. This introduced in e945059b327d42a99938b939a1be867fa023e7ba in 2005 but never built out into any of the backends. | C7: Deprecations | D7: deprecated
A8: 2.2 | B8: backend_tkagg.AxisMenu is deprecated, as it has become unused since the removal of "classic" toolbars. | C8: Deprecations | D8: deprecated, removal
A9: 2.2 | B9: Deprecated Axis.unit_data Use Axis.units (which has long existed) instead. | C9: Deprecations | D9: deprecated, instead
A10: 2.2 | B10: The matplotlib.finance, mpl_toolkits.exceltools and mpl_toolkits.gtktoolsmodules have been removed. | C10: Removals | D10: removed
A11: 2.2 | B11: The mpl_toolkits.mplot3d.art3d.iscolor function has been removed. | C11: Removals | D11: removed
A12: 2.2 | B12: The Axes.get_axis_bgcolor, Axes.set_axis_bgcolor, Bbox.update_from_data, Bbox.update_datalim_numerix, MaxNLocator.bin_boundaries methods have been removed | C12: Removals | D12: removed
A13: 2.2 | B13: The unused FONT_SCALE and fontd attributes of the RendererSVG class have been removed. | C13: Removals | D13: removed
... A128: 3.5 | B128: Modules matplotlib.backends.qt_editor.formsubplottool; use matplotlib.backends.backend_qt.SubplotToolQt instead. matplotlib.compat matplotlib.ttconv The Qt4-based backends, qt4agg and qt4cairo, have been removed. Qt4 has reached its end-of-life in 2015 and there are no releases of either PyQt4 or PySide for recent versions of Python. Please use one of the Qt5 or Qt6 backends | C128: Removals | D128: instead, removed
A129: 3.5 | B129: matplotlib.compat | C129: Removals
A130: 3.5 | B130: The following module-level classes/variables have been removed: • backend_bases.StatusbarBase and all its subclasses, and StatusBarWx; messages are displayed in the toolbar • backend_pgf.GraphicsContextPgf • MODIFIER_KEYS, SUPER, ALT, CTRL, and SHIFT of matplotlib.backends.backend_qt5agg and matplotlib.backends.backend_qt5cairo • backend_wx.DEBUG_MSG • dviread.Encoding • Fil, Fill, Filll, NegFil, NegFill, NegFilll, and SsGlue from mathtext; directly construct glue instances with Glue("fil"), etc. • mathtext.GlueSpec • OldScalarFormatter, IndexFormatter and IndexDateFormatter; use FuncFormatter instead • OldAutoLocator • AVConvBase, AVConvWriter and AVConvFileWriter. Debian 8 (2015, EOL 06/2020) and Ubuntu 14.04 (EOL 04/2019) were the last versions of Debian and Ubuntu to ship avconv. It remains possible to force the use of avconv by using the FFmpeg-based writers with rcParams["animation.ffmpeg_path"] (default: 'ffmpeg') set to "avconv". • matplotlib.axes._subplots._subplot_classes • axes_grid1.axes_rgb.RGBAxesBase; use RGBAxes instead | C130: Removals | D130: removed, instead
A131: 3.5 | B131: The following class attributes have been removed: backend_pgf.LatexManager.latex_stdin_utf8 backend_pgf.PdfPages.metadata ContourSet.ax and Quiver.ax; use ContourSet.axes or Quiver.axes as with other artists DateFormatter.illegal_s dates.YearLocator.replaced; YearLocator is now a subclass of RRuleLocator, and the attribute YearLocator.replaced has been removed. For tick locations that required modifying this, a custom rrule and RRuleLocator can be used instead. FigureManagerBase.statusbar; messages are displayed in the toolbar FileMovieWriter.clear_temp mathtext.Glue.glue_subtype MovieWriter.args_key, MovieWriter.exec_key, and HTMLWriter.args_key NavigationToolbar2QT.basedir; the base directory to the icons is os.path.join(mpl.get_data_path(), "images") NavigationToolbar2QT.ctx NavigationToolbar2QT.parent; to access the parent window, use toolbar.canvas.parent() or toolbar.parent() prevZoomRect, retinaFix, savedRetinaImage, wxoverlay, zoomAxes, zoomStartX, and zoomStartY attributes of NavigationToolbar2Wx NonUniformImage.is_grayscale, PcolorImage.is_grayscale, for consistency with AxesImage.is_grayscale. (Note that previously, these attributes were only available after rendering the image). RendererCairo.fontweights, RendererCairo.fontangles used_characters of RendererPdf, PdfFile, and RendererPS LogScale.LogTransform, LogScale.InvertedLogTransform, SymmetricalScale.SymmetricalTransform, and SymmetricalScale.InvertedSymmetricalTransform; directly access the transform classes from matplotlib.scale cachedir, rgba_arrayd, serif, sans_serif, cursive, and monospace attributes of TexManager axleft, axright, axbottom, axtop, axwspace, and axhspace attributes of widgets.SubplotTool; access the ax attribute of the corresponding slider widgets.TextBox.params_to_disable angle_helper.LocatorBase.den; it has been renamed to nbins axes_grid.CbarAxesBase.cbid and axes_grid.CbarAxesBase.locator; use mappable.colorbar_cid or colorbar.locator instead | C131: Removals | D131: removed, instead
A132: 3.5 | B132: The following class methods have been removed: • Axes.update_datalim_bounds; use ax.dataLim.set(Bbox.union([ax.dataLim, bounds])) • pan and zoom methods of Axis and Locator have been removed; panning and zooming are now implemented using the start_pan, drag_pan, and end_pan methods of Axes • .BboxBase.inverse_transformed; call BboxBase.transformed on the inverted() transform • Collection.set_offset_position and Collection.get_offset_positionhave been removed; the offset_position of the Collection class is now "screen" • Colorbar.on_mappable_changed and Colorbar.update_bruteforce; use Colorbar.update_normal() instead • docstring.Substitution.from_params has been removed; directly assign to params of docstring.Substitution instead • DraggableBase.artist_picker; set the artist's picker instead • DraggableBase.on_motion_blit; use DraggableBase.on_motion instead • FigureCanvasGTK3._renderer_init • Locator.refresh() and the associated helper methods NavigationToolbar2.draw() and ToolViewsPositions.refresh_locators() • track_characters and merge_used_characters of RendererPdf, PdfFile, and RendererPS • RendererWx.get_gc • SubplotSpec.get_rows_columns; use the GridSpec.nrows, GridSpec.ncols, SubplotSpec.rowspan, and SubplotSpec.colspanproperties instead. • ScalarMappable.update_dict, ScalarMappable.add_checker(), and ScalarMappable.check_update(); register a callback in ScalarMappable.callbacks to be notified of updates • TexManager.make_tex_preview and TexManager.make_dvi_preview • funcleft, funcright, funcbottom, functop, funcwspace, and funchspace methods of widgets.SubplotTool • axes_grid1.axes_rgb.RGBAxes.add_RGB_to_figure • axisartist.axis_artist.AxisArtist.dpi_transform • axisartist.grid_finder.MaxNLocator.set_factor and axisartist.grid_finder.FixedLocator.set_factor; the factor is always 1 now | C132: Removals | D132: removed, instead
A133: 3.5 | B133: bezier.make_path_regular has been removed; use Path.cleaned() (or Path.cleaned(curves=True), etc.) instead, but note that these methods add a STOP code at the end of the path. | C133: Removals | D133: removed, instead
A134: 3.5 | B134: bezier.concatenate_paths has been removed; use Path.make_compound_path() instead. | C134: Removals | D134: removed, instead
A135: 3.5 | B135: cbook.local_over_kwdict has been removed; use cbook.normalize_kwargs instead. | C135: Removals | D135: removed, instead
A136: 3.5 | B136: qt_compat.is_pyqt5 has been removed due to the release of PyQt6. The Qt version can be checked using QtCore.qVersion(). | C136: Removals | D136: removed
A137: 3.5 | B137: testing.compare.make_external_conversion_command has been removed. | C137: Removals | D137: removed
A138: 3.5 | B138: axes_grid1.axes_rgb.imshow_rgb has been removed; use imshow(np.dstack([r, g, b])) instead. | C138: Removals | D138: removed, instead
A139: 3.5 | B139: The animation.avconv_path and animation.avconv_args rcParams have been removed. | C139: Removals | D139: removed
A140: 3.5 | B140: The animation.html_args rcParam has been removed. | C140: Removals | D140: removed
A141: 3.5 | B141: The keymap.all_axes rcParam has been removed. | C141: Removals | D141: removed
... A179: 3.6 | B179: The following functions have been removed; backend_template.new_figure_manager(), backend_template.new_figure_manager_given_figure(), and backend_template.draw_if_interactive() have been removed, as part of the introduction of the simplified backend API. Deprecation-related re-imports cbook.deprecated(), and cbook.warn_deprecated(). colorbar.colorbar_factory(); use Colorbar instead. colorbar.make_axes_kw_doc() mathtext.Error() mathtext.ship() mathtext.tex2uni() axes_grid1.parasite_axes.parasite_axes_auxtrans_class_factory(); use parasite_axes_class_factory instead. sphinext.plot_directive.align(); use docutils.parsers.rst.directives.images.Image.align instead. | C179: Remmovals | D179: removed, instead
A180: total= | B180: 178
D182: 这里有一条条目没有keyword

Sheet redis-py
A1: version | B1: entries for deprecation changes | C1: section | D1: keyword
A2: 4.3.0 | B2: Rename 'update_supported_erros' to 'update_supported_errors' in Retry module | C2: Bug Fixes | D2: rename
A3: 4.3.6 | B3: -
A4: 4.4.2 | B4: -
A5: 4.5.5 | B5: -
A6: 5.0.6 | B6: -
A7: total= | B7: 1

Sheet tornado
A1: version | B1: entries for deprecation changes | C1: section | D1: keyword
A2: 4.3 | B2: tornado.gen Multi and multi_future are deprecated and replaced by a unified function multi. | C2: Installation | D2: deprecated, replaced
A3: 4.4 | B3: -
A4: 4.5 | B4: tornado.gen yield None is now equivalent to yield gen.moment. moment is deprecated. This improves compatibility with asyncio. | C4: General changes | D4: deprecated
A5: 4.5.1 | B5: -
A6: 6.3.2 | B6: -
A7: total= | B7: 2

Sheet NetworkX
A1: version | B1: entries for deprecation changes | C1: section | D1: keyword
A2: 0.26 | B2: -
A3: 1.6 | B3: Isomorphisms Node and edge attributes are now more easily incorporated into isomorphism checks via the ‘node_match’ and ‘edge_match’ parameters. As part of this change, the following classes were removed: WeightedGraphMatcher WeightedDiGraphMatcher WeightedMultiGraphMatcher WeightedMultiDiGraphMatcher | D3: removed
A4: 2.8.2 | B4: -
A5: 2.8.5 | B5: make lazy_import private and remove its internal use | D5: private, remove, internal
A6: 2.8.6 | B6: -
A7: total= | B7: 2

Sheet rich
A1: version | B1: entries for deprecation changes | C1: section | D1: keyword
A2: 0.6.0 | B2: -
A3: 9.12.2 | B3: -
A4: 12.2.0 | B4: -
A5: 12.4.4 | B5: -
A6: 13.4.2 | B6: -
A7: total= | B7: 0

Sheet tensorflow
A1: version | B1: entries for deprecation changes | C1: section | D1: keyword
A2: 1.13.1 | B2: TensorFlow Lite has moved from contrib to core. This means that Python modules are under tf.lite and source code is now under tensorflow/lite rather than tensorflow/contrib/lite. | C2: Major Features and Improvements | D2: moved
A3: 1.13.1 | B3: Removing deprecations for the following endpoints: tf.acos, tf.acosh, tf.add, tf.as_string, tf.asin, tf.asinh, tf.atan, tf.atan2, tf.atanh, tf.cos, tf.cosh, tf.equal, tf.exp, tf.floor, tf.greater, tf.greater_equal, tf.less, tf.less_equal, tf.log, tf.logp1, tf.logical_and, tf.logical_not, tf.logical_or, tf.maximum, tf.minimum, tf.not_equal, tf.sin, tf.sinh, tf.tan | C3: Bug Fixes and Other Changes/Deprecations and Symbol renames. | D3: removing, deprecations
A4: 1.13.1 | B4: Deprecate tf.data.Dataset.shard. | C4: Bug Fixes and Other Changes/Deprecations and Symbol renames. | D4: deprecate
A5: 1.13.1 | B5: Deprecate saved_model.loader.load which is replaced by saved_model.load and saved_model.main_op, which will be replaced by saved_model.main_op in V2. | C5: Bug Fixes and Other Changes/Deprecations and Symbol renames. | D5: deprecate, replaced
A6: 1.13.1 | B6: Deprecate tf.QUANTIZED_DTYPES. The official new symbol is tf.dtypes.QUANTIZED_DTYPES. | C6: Bug Fixes and Other Changes/Deprecations and Symbol renames. | D6: deprecate
A7: 1.13.1 | B7: Deprecate Variable.count_up_to and tf.count_up_to in favor of Dataset.range. | C7: Bug Fixes and Other Changes/Deprecations and Symbol renames. | D7: deprecate, in favor of
A8: 1.13.1 | B8: Export confusion_matrix op as tf.math.confusion_matrix instead of tf.train.confusion_matrix. | C8: Bug Fixes and Other Changes/Deprecations and Symbol renames. | D8: instead
A9: 1.13.1 | B9: Add tf.dtypes. endpoint for every constant in dtypes.py; moving endpoints in versions.py to corresponding endpoints in tf.sysconfig. and tf.version.; moving all constants under tf.saved_model submodules to tf.saved_model module. New endpoints are added in V1 and V2 but existing endpoint removals are only applied in V2. | C9: Bug Fixes and Other Changes/Deprecations and Symbol renames. | D9: moving, removal
A10: 1.13.1 | B10: TensorFlow Lite Move from tensorflow/contrib/lite to tensorflow/lite. | C10: Bug Fixes and Other Changes/TensorFlow Lite | D10: move
A11: 1.13.1 | B11: tf.contrib Move tf.contrib.signal to tf.signal (preserving aliases in tf.contrib.signal). | C11: Bug Fixes and Other Changes/tf.contrib | D11: move
A12: 1.13.1 | B12: tf.data: Deprecate tf.data.Dataset.make_initializable_iterator() in V1, removed it from V2, and added tf.compat.v1.data.make_initializable_iterator(). | C12: Bug Fixes and Other Changes/tf.contrib | D12: deprecate, removed
A13: 1.13.1 | B13: Toolchains Removed :android_tensorflow_lib_selective_registration* targets, use :android_tensorflow_lib_lite* targets instead | C13: Bug Fixes and Other Changes/Toolchains | D13: removed, instead
A14: 2.0.3 | B14: -
A15: 2.1.0 | B15: Deletes Operation.traceback_with_start_lines for which we know of no usages. | C15: Breaking Changes | D15: deletes
A16: 2.1.0 | B16: tf.config.experimentalVirtualDeviceConfiguration has been renamed to tf.config.LogicalDeviceConfiguration. | C16: Breaking Changes | D16: renamed
A17: 2.1.0 | B17: tf.config.experimental_list_devices has been removed, please use tf.config.list_logical_devices. | C17: Breaking Changes | D17: removed
A18: 2.1.0 | B18: tf.keras Model.fit_generator, Model.evaluate_generator, Model.predict_generator, Model.train_on_batch, Model.test_on_batch, and Model.predict_on_batch methods now respect the run_eagerly property, and will correctly run using tf.function by default. Note that Model.fit_generator, Model.evaluate_generator, and Model.predict_generator are deprecated endpoints. They are subsumed by Model.fit, Model.evaluate, and Model.predict which now support generators and Sequences | C18: Bug Fixes and Other Changes | D18: deprecated, subsumed
A19: 2.8.0 | B19: Add tf.config.experimental.enable_op_determinism, which makes TensorFlow ops run deterministically at the cost of performance. Replaces the TF_DETERMINISTIC_OPS environmental variable, which is now deprecated. The "Bug Fixes and Other Changes" section lists more determinism-related changes. | C19: Major Features and Improvements | D19: replaces, deprecated
A20: 2.8.0 | B20: tf.keras: Removed keras.layers.experimental.preprocessing.CategoryCrossing. Users should migrate to the HashedCrossing layer or use tf.sparse.cross/tf.ragged.cross directly. | C20: Bug Fixes and Other Changes | D20: removed, migrate
A21: 2.8.0 | B21: tf.keras: tf.keras.callbacks.experimental.BackupAndRestore is now available as tf.keras.callbacks.BackupAndRestore. The experimental endpoint is deprecated and will be removed in a future release. | C21: Bug Fixes and Other Changes | D21: deprecated, removed
A22: 2.8.0 | B22: tf.keras: tf.keras.experimental.SidecarEvaluator is now available as tf.keras.utils.SidecarEvaluator. The experimental endpoint is deprecated and will be removed in a future release. | C22: Bug Fixes and Other Changes | D22: deprecated, removed
A23: 2.15.0 | B23: tf.types.experimental.GenericFunction has been renamed to tf.types.experimental.PolymorphicFunction. | C23: Breaking Changes | D23: renamed
A24: 2.15.0 | B24: tf.data: Moved option warm_start from tf.data.experimental.OptimizationOptions to tf.data.Options. | C24: Major Features and Improvements | D24: moved
A25: 2.15.0 | B25: tf.estimator The tf.estimator API removal is in progress and will be targeted for the 2.16 release | C25: Bug Fixes and Other Changes | D25: removal
A26: total= | B26: 23

Sheet fastAPI
A1: version | B1: entries for deprecation changes | C1: section | D1: keyword
A2: 0.42.0 | B2: -
A3: 0.55.0 | B3: -
A4: 0.89.1 | B4: -
A5: 0.92.0 | B5: -
A6: 0.100.1 | B6: -
A7: total= | B7: 0

Sheet httpx
A1: version | B1: entries for deprecation changes | C1: section | D1: keyword
A2: 0.9.1 | B2: -
A3: 0.14.0 | B3: You should now use httpx.codes consistently instead of httpx.StatusCodes. | D3: instead
A4: 0.14.0 | B4: Use httpx.Limits() instead of httpx.PoolLimits(), and limits=... instead of pool_limits=.... | D4: instead
A5: 0.14.0 | B5: The multidict methods Headers.getlist() and QueryParams.getlist() are deprecated in favour of more consistent .get_list() variants. | D5: deprecated, in favour of
A6: 0.14.0 | B6: The URL.is_ssl property is deprecated in favour of URL.scheme == "https". | D6: deprecated, in favour of
A7: 0.14.0 | B7: The following previously had nominally public names on the client, but were all undocumented and intended solely for internal usage. They are all now replaced with underscored names, and should not be relied on or accessed. These changes should not affect users who have been working from the httpx documentation. .merge_url(), .merge_headers(), .merge_cookies(), .merge_queryparams() .build_auth(), .build_redirect_request() .redirect_method(), .redirect_url(), .redirect_headers(), .redirect_stream() .send_handling_redirects(), .send_handling_auth(), .send_single_request() .init_transport(), .init_proxy_transport() .proxies, .transport, .netrc, .get_proxy_map() | D7: internal, replaced
A8: 0.14.0 | B8: Drop ASGIDispatch, WSGIDispatch, which have been replaced by ASGITransport, WSGITransport. | D8: drop, replaced
A9: 0.14.0 | B9: Drop dispatch=...`` on client, which has been replaced by transport=...`` | D9: drop, replaced
A10: 0.14.0 | B10: Drop soft_limit, hard_limit, which have been replaced by max_keepalive and max_connections. | D10: drop, replaced
A11: 0.14.0 | B11: Drop Response.stream and Response.raw, which have been replaced by ``.aiter_bytes and .aiter_raw. | D11: drop, replaced
A12: 0.14.0 | B12: Drop proxies=<transport instance> in favor of proxies=httpx.Proxy(...). | D12: drop, in favor of
A13: 0.14.0 | B13: Use httpx.codes consistently in favour of httpx.StatusCodes which is placed into deprecation | C13: Changed | D13: in favour of, deprecation
A14: 0.14.0 | B14: Use httpx.Limits() instead of httpx.PoolLimits(), and limits=... instead of pool_limits=.... | C14: Changed | D14: instead
A15: 0.14.0 | B15: The multidict methods Headers.getlist and QueryParams.getlist are deprecated in favour of more consistent .get_list()variants. | C15: Changed | D15: deprecated, in favour of
A16: 0.14.0 | B16: Drop unnecessary url.full_path = ... property setter. | C16: Changed | D16: drop
A17: 0.14.0 | B17: The URL.is_ssl property is deprecated in favour of URL.scheme == "https". | C17: Changed | D17: deprecated, in favour of
A18: 0.14.2 | B18: -
A19: 0.15.3 | B19: -
A20: 0.16.1 | B20: -
A21: total= | B21: 15

Sheet transformers
A1: version | B1: entries for deprecation changes | C1: section | D1: keyword
A2: 2.4.0 | B2: -
A3: 3.4.0 | B3: Remove config assumption in Trainer | C3: Improvements made to the Trainer | D3: remove
A4: 3.4.0 | B4: Adding Fast tokenizers for SentencePiece based tokenizers - Breaking: remove Transfo-XL fast tokenizer | C4: General improvements and bugfixes | D4: remove
A5: 3.4.0 | B5: Remove duplicated mish activation function | C5: General improvements and bugfixes | D5: remove
A6: 4.11.3 | B6: -
A7: 4.39.3 | B7: -
A8: 4.47.1 | B8: -
A9: total= | B9: 3

Sheet django
A1: version | B1: entries for deprecation changes | C1: section | D1: keyword
A2: 0.95 | B2: -
A3: 1.7.1 | B3: -
A4: 1.11.11 | B4: -
A5: 4.0.5 | B5: -
A6: 4.1.3 | B6: -
A7: total= | B7: 0

Sheet xgboost
A1: version | B1: entries for deprecation changes | C1: section | D1: keyword
A2: 1.3.1 | B2: Remove cupy.array_equal, since it's not compatible with cuPy 7.8 | D2: remove
A3: 1.7.1 | B3: -
A4: 1.7.3 | B4: -
A5: 1.7.5 | B5: -
A6: 2.1.1 | B6: -
A7: total= | B7: 1

Sheet keras
A1: version | B1: entries for deprecation changes | C1: section | D1: keyword
A2: 2.1.2 | B2: -
A3: 2.15.0 | B3: -
A4: 3.0.1 | B4: -
A5: 3.0.2 | B5: -
A6: 3.0.3 | B6: -
A7: total= | B7: 0

Sheet pytorch
A1: version | B1: entries for deprecation changes | C1: section | D1: keyword
A2: 0.4.0 | B2: Tensors and Variables have merged | C2: Major Core changes | D2: merged
A3: 0.4.0 | B3: Deprecation of the volatile flag | C3: Major Core changes | D3: deprecation
A4: 0.4.0 | B4: Deprecation of volatile flag The volatile flag is now deprecated and has no effect. Previously, any computation that involves a Variable with volatile=True won't be tracked by autograd. This has now been replaced by a set of more flexible context managers including torch.no_grad(), torch.set_grad_enabled(grad_mode), and others. | C4: Major Core changes | D4: deprecation, deprecated, replaced
A5: 0.4.0 | B5: Deprecate out-of-place Tensor.resize and Tensor.resize_as. These have weird semantics and are hard to use correctly. Please use their in-place variants Tensor.resize_ and Tensor.resize_as_. | C5: Tensor | D5: deprecate
A6: 0.4.0 | B6: Renamed torch.nn.init.* methods to have an underscore in the end, as they operate in-place, and deprecate the old versions | C6: Neural Networks | D6: renamed, deprecate
A7: 1.3.0 | B7: torch.gels: removed deprecated operator, use torch.lstsq instead. | C7: Breaking Changes | D7: removed, deprecated
A8: 1.3.0 | B8: utils.data.DataLoader: made a number of Iterator attributes private | C8: Breaking Changes | D8: private
A9: 1.5.0 | B9: -
A10: 1.9.0 | B10: import torch.tensor as tensor is no longer supported (#53424). Instead, use from torch import tensor | C10: Backwards Incompatible Changes | D10: no longer supported, instead
A11: 1.9.0 | B11: torch.floor_divide has been deprecated in favor of torch.div(..., rounding_mode=‘floor’) | C11: Deprecations | D11: deprecated, in favor of
A12: 1.9.0 | B12: Older linear algebra operations have been deprecated in favor of their new linalg module counterparts. Namely: torch.{cholesky, qr, symeig, chain_matmul, solve, eig, matrix_rank, lstsq} have been deprecated in favor of torch.linalg.{cholesky, qr, symeig, chain_matmul, solve, eig, matrix_rank, lstsq} (#57725,#57745, #57732,#53453, #57741, #57727, #57734, #57743). torch.norm has been deprecated in favor of the new linalg module norm functions: torch.linalg.vector_norm, torch.linalg.matrix_norm, and torch.linalg.norm (#57986). Aliased torch.det, torch.slogdet, torch.matrix_power, torch.inverse, and torch.pinverse to their linalg module counterparts | C12: Deprecations | D12: deprecated, in favor of
A13: 1.9.0 | B13: Deprecated get_analytical_jacobian and get_numerical_jacobian (#54378, #54049). torch.autograd.gradcheck.get_analytical_jacobian and torch.autograd.gradcheck.get_numerical_jacobian are internal-facing functions that are not a part of our public API. We’ve refactored some PyTorch internals to work without it and will remove it in a future release. For gradient checking purposes, please use torch.autograd.gradcheck. | C13: Deprecations | D13: deprecated, remove
A14: 1.9.0 | B14: Renamed Callable to MapIterDataPipe | C14: New features | D14: renamed
A15: 2.4.0 | B15: Delete torch.autograd.function.traceable APIs (#122817) The torch.autograd.function.traceable(...) API, which sets the is_traceable class attribute on a torch.autograd.Function class was deprecated in 2.3 and is now being deleted. This API does not do anything and was only meant for internal purposes. | C15: Backwards Incompatible Changes | D15: delete, deprecated, internal
A16: 2.4.0 | B16: Pipelining Retire torch.distributed.pipeline (#127354) In 2.3 and before, users can do: import torch.distributed.pipeline # warning saying that this will be removed and users need to migrate to torch.distributed.pipelining But from 2.4 forward, if users write the code above, users will get a ModuleNotFound error. Instead, they should use torch.distributed.pipelining: import torch.distributed.pipeline # -> ModuleNotFoundError import torch.distributed.pipelining | C16: Backwards Incompatible Changes | D16: instead, migrate, retire, removed
A17: 2.4.0 | B17: ONNX • Remove caffe2 contrib and experiments | C17: Backwards Incompatible Changes | D17: remove
A18: 2.4.0 | B18: Release Engineering • Remove of QNNPACK third-party module | C18: Deprecations | D18: remove
A19: 2.4.0 | B19: Optim Deprecate LRScheduler.print_lr | C19: Deprecations | D19: deprecate
A20: 2.4.0 | B20: FullyShardedDataParallel (FSDP) Deprecate FSDP.state_dict_type and redirect users to distributed_state_dict from 2.4 forward, if users call state_dict or set state_dict with the FSDP.state_dict_type, users will see warnings. And the recommended solution now is to use get_model_state_dict and set_model_state_dict directly | C20: Deprecations | D20: deprecate, redirect, recommended
A21: 2.4.0 | B21: Quantization Remove deprecated torch._aminmax operator (#125995). torch._aminmax -> torch.aminmax instead | C21: Deprecations | D21: remove, deprecated, instead
... A28: 2.4.0 | B28: FullyShardedDataParallel (FSDP) private _unshard API | C28: Improvements | D28: private
A29: total= | B29: 26

Sheet plotly.py
A1: version | B1: entries for deprecation changes | C1: section | D1: keyword
A2: 1.8.9 | B2: -
A3: 3.5.0 | B3: -
A4: 4.8.1 | B4: -
A5: 5.10.0 | B5: -
A6: 5.24.0 | B6: Deprecate mapbox traces and mapbox subplot | C6: Update | D6: deprecate
A7: total= | B7: 1

Sheet dask
A1: version | B1: entries for deprecation changes | C1: section | D1: keyword
A2: 0.20.0 | B2: Remove dask.array.ghost module | C2: Array | D2: remove
A3: 0.20.0 | B3: Remove Series.to_parquet | C3: Dataframe | D3: remove
A4: 2.10.1 | B4: -
A5: 2021.12.0 | B5: -
A6: 2022.8.1 | B6: -
A7: 2023.3.1 | B7: -
A8: total= | B8: 2

Sheet polars
A1: version | B1: entries for deprecation changes | C1: section | D1: keyword
A2: 0.14.18 | B2: -
A3: 0.15.16 | B3: -
A4: 0.17.5 | B4: -
A5: 0.20.14 | B5: Rename utils module to _utils to explicitly mark it as private | C5: Other improvements | D5: rename, private
A6: 1.14.0 | B6: -
A7: total= | B7: 1

Sheet loguru
A1: version | B1: entries for deprecation changes | C1: section | D1: keyword
A2: 0.2.2 | B2: Deprecate logger.start() and logger.stop() methods in favor of logger.add() and logger.remove() | D2: deprecate, in favor of
A3: 0.2.3 | B3: -
A4: 0.2.5 | B4: -
A5: 0.3.2 | B5: -
A6: 0.7.3 | B6: -
A7: total= | B7: 1

Sheet LightGBM
A1: version | B1: entries for deprecation changes | C1: section | D1: keyword
A2: 2.1.2 | B2: -
A3: 2.2.0 | B3: -
A4: 3.1.0 | B4: -
A5: 3.3.0 | B5: python] rename print_evaluation() into log_evaluation() | C5: Breaking | D5: rename
A6: 3.3.3 | B6: -
A7: total= | B7: 1

Sheet sympy
A1: version | B1: entries for deprecation changes | C1: section | D1: keyword
A2: 0.7.4 | B2: Removed deprecated Real class and is_Real property of Basic | C2: Backwards compatibility breaks and deprecations | D2: removed, deprecated
A3: 0.7.4 | B3: Removed deprecated 'each_char' option for symbols() | C3: Backwards compatibility breaks and deprecations | D3: removed, deprecated
A4: 0.7.4 | B4: The viewer="StringIO" option to preview() has been deprecated. Use viewer="BytesIO" instead. | C4: Backwards compatibility breaks and deprecations | D4: deprecated, instead
A5: 0.7.4 | B5: TransformationSet has been renamed to ImageSet. Added public facing imageset function. | C5: Backwards compatibility breaks and deprecations | D5: renamed
A6: 0.7.6 | B6: The subset() method in sympy.core.sets is marked as being deprecated and will be removed in a future release (issue). Instead, the is_subset() method should be used. | C6: Backwards compatibility breaks and deprecations | D6: deprecated, removed, instead
A7: 0.7.6 | B7: In physics.mechanics, KanesMethod.linearize has a new interface. Old code should be changed to use this instead. See docstring for information | C7: Backwards compatibility breaks and deprecations | D7: instead
A8: 0.7.6 | B8: physics.gaussopt has been moved to physics.optics.gaussopt. You can still import it from the previous location but it may result in a deprecation warning. | C8: Backwards compatibility breaks and deprecations | D8: moved, deprecation
A9: 0.7.6 | B9: Removed is_finite assumption (see #7891). Use instead a combination of "is_bounded and is_nonzero" assumptions. | C9: Backwards compatibility breaks and deprecations | D9: removed, instead
A10: 0.7.6 | B10: is_bounded and is_unbounded assumptions were renamed to is_finite and is_infinite | C10: Backwards compatibility breaks and deprecations | D10: renamed
A11: 0.7.6 | B11: Removed is_infinitesimal assumption | C11: Backwards compatibility breaks and deprecations | D11: removed
A12: 0.7.6 | B12: Removed is_real property for Sets, use set.is_subset(Reals) instead | C12: Backwards compatibility breaks and deprecations | D12: removed, instead
... A30: 1.10 | B30: utilities interactive_traversal is moved from utilities.iterables to interactive.traversal. | C30: changes | D30: moved
A31: 1.10.1 | B31: -
A32: total= | B32: 29

Sheet spaCy
A1: version | B1: entries for deprecation changes | C1: section | D1: keyword
A2: 2.0.11 | B2: -
A3: 2.2.4 | B3: -
A4: 2.3.6 | B4: -
A5: 3.1.6 | B5: -
A6: 3.5.1 | B6: -
A7: total= | B7: 0

Sheet gensim
A1: version | B1: entries for deprecation changes | C1: section | D1: keyword
A2: 0.5.0 | B2: -
A3: 0.7.8 | B3: -
A4: 0.8.3 | B4: -
A5: 0.9.0 | B5: -
A6: 3.7.3 | B6: Remove gensim.models.FastText.load_fasttext_format: use load_facebook_vectors to load embeddings only (faster, less CPU/memory usage, does not support training continuation) and load_facebook_model to load full model (slower, more CPU/memory intensive, supports training continuation) gensim.models.wrappers.fasttext (obsoleted by the new native gensim.models.fasttext implementation) gensim.examples gensim.nosy gensim.scripts.word2vec_standalone gensim.scripts.make_wiki_lemma gensim.scripts.make_wiki_online gensim.scripts.make_wiki_online_lemma gensim.scripts.make_wiki_online_nodebug gensim.scripts.make_wiki (all of these obsoleted by the new native gensim.scripts.segment_wiki implementation) "deprecated" functions and attributes | C6: Deprecations(will be removed in the next major release) | D6: remove
A7: 3.7.3 | B7: Move gensim.scripts.make_wikicorpus ➡ gensim.scripts.make_wiki.py gensim.summarization ➡ gensim.models.summarization gensim.topic_coherence ➡ gensim.models._coherence gensim.utils ➡ gensim.utils.utils (old imports will continue to work) gensim.parsing.* ➡ gensim.utils.text_utils | C7: Deprecations(will be removed in the next major release) | D7: move
A8: total= | B8: 2

Sheet jax
A1: version | B1: entries for deprecation changes | C1: section | D1: keyword
A2: 0.2.20 | B2: -
A3: 0.3.5 | B3: the private lax_numpy submodule is no longer exposed in the jax.numpynamespace (#10029). | C3: Changes | D3: no longer exposed, private
A4: 0.3.5 | B4: jax.experimental.sharded_jit has been deprecated and will be removed soon. | C4: Changes | D4: deprecated, removed
A5: 0.3.5 | B5: jax.nn.normalize() is being deprecated. Use jax.nn.standardize() instead | C5: Deprecations | D5: deprecated, instead
A6: 0.3.5 | B6: jax.tree_util.tree_multimap() is deprecated. Use jax.tree_util.tree_map() instead | C6: Deprecations | D6: deprecated, instead
A7: 0.3.5 | B7: jax.experimental.sharded_jit is deprecated. Use pjit instead. | C7: Deprecations | D7: deprecated, instead
A8: 0.4.11 | B8: The following APIs have been removed after a 3 month deprecation period, in accordance with the API compatibility policy: jax.experimental.PartitionSpec: use jax.sharding.PartitionSpec. jax.experimental.maps.Mesh: use jax.sharding.Mesh jax.experimental.pjit.NamedSharding: use jax.sharding.NamedSharding. jax.experimental.pjit.PartitionSpec: use jax.sharding.PartitionSpec. jax.experimental.pjit.FROM_GDA. Instead pass sharded jax.Array objects as input and remove the optional in_shardings argument to pjit. jax.interpreters.pxla.PartitionSpec: use jax.sharding.PartitionSpec. jax.interpreters.pxla.Mesh: use jax.sharding.Mesh jax.interpreters.xla.Buffer: use jax.Array. jax.interpreters.xla.Device: use jax.Device. jax.interpreters.xla.DeviceArray: use jax.Array. jax.interpreters.xla.device_put: use jax.device_put. jax.interpreters.xla.xla_call_p: use jax.experimental.pjit.pjit_p. | C8: Deprecations | D8: removed, deprecation, instead
A9: 0.4.17 | B9: Removed the deprecated module jax.abstract_arrays and all its contents. | C9: Deprecations | D9: removed, deprecated
A10: 0.4.18 | B10: Named key constructors in jax.random are deprecated. Pass the impl argument to jax.random.PRNGKey() or jax.random.key() instead: random.threefry2x32_key(seed) becomes random.PRNGKey(seed, impl='threefry2x32') random.rbg_key(seed) becomes random.PRNGKey(seed, impl='rbg') random.unsafe_rbg_key(seed) becomes random.PRNGKey(seed, impl='unsafe_rbg') | C10: Deprecations | D10: deprecated, instead, becomes
A11: total= | B11: 8

Sheet aiohttp
A1: version | B1: entries for deprecation changes | C1: section | D1: keyword
A2: 0.18.4 | B2: -
A3: 3.4.4 | B3: -
A4: 3.6.2 | B4: -
A5: 3.9.3 | B5: -
A6: 3.10.2 | B6: Removed Request.wait_for_disconnection(), which was mistakenly added briefly in 3.10.0 | C6: Removals and backward incompatible breaking changes | D6: removed
A7: total= | B7: 1

Sheet faker
A1: version | B1: entries for deprecation changes | C1: section | D1: keyword
A2: 0.4 | B2: -
A3: 9.3.0 | B3: -
A4: 25.2.0 | B4: -
A5: 25.8.0 | B5: -
A6: 28.2.0 | B6: -
A7: total= | B7: 0

Sheet keywords analysis
A1: total= | B1: =request!B7+numpy!B6+pandas!B65+click!B7+flask!B7+pydantic!B7+SciPy!B12+pillow!B7+'scikit-learn'!B9+matplotlib!B180+'redis-py'!B7+tornado!B7+NetworkX!B7+rich!B7+tensorflow!B26+fastAPI!B7+httpx!B21+transformers!B9+django!B7+xgboost!B7+keras!B7+pytorch!B29+plotly.py!B7+dask!B8+polars!B7+loguru!B7+LightGBM!B7+sympy!B32+spaCy!B7+gensim!B8+jax!B11+aiohttp!B7+faker!B7 -> 371 | D1: keyword | E1: covered entries | G1: coverage | I1: stemmed keywords | J1: covered entries(reference value) | K1: covered entries(actual value) | L1: coverage | Q1: gradually enlarge the set
D2: deprecate | E2: =COUNTIF(request!D:D, "*"&D2&"*")+COUNTIF(numpy!D:D, "*"&D2&"*")+COUNTIF(pandas!D:D, "*"&D2&"*")+COUNTIF(click!D:D, "*"&D2&"*")+COUNTIF(flask!D:D, "*"&D2&"*")+COUNTIF(pydantic!D:D, "*"&D2&"*")+COUNTIF(SciPy!D:D, "*"&D2&"*")+COUNTIF(pillow!D:D, "*"&D2&"*")+COUNTIF('scikit-learn'!D:D, "*"&D2&"*")+COUNTIF(matplotlib!D:D, "*"&D2&"*")+COUNTIF('redis-py'!D:D, "*"&D2&"*")+COUNTIF(tornado!D:D, "*"&D2&"*")+COUNTIF(NetworkX!D:D, "*"&D2&"*")+COUNTIF(rich!D:D, "*"&D2&"*")+COUNTIF(tensorflow!D:D, "*"&D2&"*")+COUNTIF(fastAPI!D:D, "*"&D2&"*")+COUNTIF(httpx!D:D, "*"&D2&"*")+COUNTIF(transformers!D:D, "*"&D2&"*")+COUNTIF(django!D:D, "*"&D2&"*")+COUNTIF(xgboost!D:D, "*"&D2&"*")+COUNTIF(keras!D:D, "*"&D2&"*")+COUNTIF(pytorch!D:D, "*"&D2&"*")+COUNTIF(plotly.py!D:D, "*"&D2&"*")+COUNTIF(dask!D:D, "*"&D2&"*")+COUNTIF(polars!D:D, "*"&D2&"*")+COUNTIF(loguru!D:D, "*"&D2&"*")+COUNTIF(LightGBM!D:D, "*"&D2&"*")+COUNTIF(sympy!D:D, "*"&D2&"*")+COUNTIF(spaCy!D:D, "*"&D2&"*")+COUNTIF(gensim!D:D, "*"&D2&"*")+COUNTIF(jax!D:D, "*"&D2&"*")+COUNTIF(aiohttp!D:D, "*"&D2&"*")+COUNTIF(faker!D:D, "*"&D2&"*") -> 201 | F2: =E2-E3-E4 -> 13 | I2: deprecat | J2: =F2+E3+E4+F5+E6 -> 216 | K2: =COUNTIF(request!D:D, "*"&I2&"*")+COUNTIF(numpy!D:D, "*"&I2&"*")+COUNTIF(pandas!D:D, "*"&I2&"*")+COUNTIF(click!D:D, "*"&I2&"*")+COUNTIF(flask!D:D, "*"&I2&"*")+COUNTIF(pydantic!D:D, "*"&I2&"*")+COUNTIF(SciPy!D:D, "*"&I2&"*")+COUNTIF(pillow!D:D, "*"&I2&"*")+COUNTIF('scikit-learn'!D:D, "*"&I2&"*")+COUNTIF(matplotlib!D:D, "*"&I2&"*")+COUNTIF('redis-py'!D:D, "*"&I2&"*")+COUNTIF(tornado!D:D, "*"&I2&"*")+COUNTIF(NetworkX!D:D, "*"&I2&"*")+COUNTIF(rich!D:D, "*"&I2&"*")+COUNTIF(tensorflow!D:D, "*"&I2&"*")+COUNTIF(fastAPI!D:D, "*"&I2&"*")+COUNTIF(httpx!D:D, "*"&I2&"*")+COUNTIF(transformers!D:D, "*"&I2&"*")+COUNTIF(django!D:D, "*"&I2&"*")+COUNTIF(xgboost!D:D, "*"&I2&"*")+COUNTIF(keras!D:D, "*"&I2&"*")+COUNTIF(pytorch!D:D, "*"&I2&"*")+COUNTIF(plotly.py!D:D, "*"&I2&"*")+COUNTIF(dask!D:D, "*"&I2&"*")+COUNTIF(polars!D:D, "*"&I2&"*")+COUNTIF(loguru!D:D, "*"&I2&"*")+COUNTIF(LightGBM!D:D, "*"&I2&"*")+COUNTIF(sympy!D:D, "*"&I2&"*")+COUNTIF(spaCy!D:D, "*"&I2&"*")+COUNTIF(gensim!D:D, "*"&I2&"*")+COUNTIF(jax!D:D, "*"&I2&"*")+COUNTIF(aiohttp!D:D, "*"&I2&"*")+COUNTIF(faker!D:D, "*"&I2&"*") -> 211 | L2: =K2/B$1 -> 0.56873315 | Q2: deprecat | R2: =COUNTIFS(request!$D:$D, "*"&$Q2&"*")+COUNTIFS(numpy!$D:$D, "*"&$Q2&"*")+COUNTIFS(pandas!$D:$D, "*"&$Q2&"*")+COUNTIFS(click!$D:$D, "*"&$Q2&"*")+COUNTIFS(flask!$D:$D, "*"&$Q2&"*")+COUNTIFS(pydantic!$D:$D, "*"&$Q2&"*")+COUNTIFS(SciPy!$D:$D, "*"&$Q2&"*")+COUNTIFS(pillow!$D:$D, "*"&$Q2&"*")+COUNTIFS('scikit-learn'!$D:$D, "*"&$Q2&"*")+COUNTIFS(matplotlib!$D:$D, "*"&$Q2&"*")+COUNTIFS('redis-py'!$D:$D, "*"&$Q2&"*")+COUNTIFS(tornado!$D:$D, "*"&$Q2&"*")+COUNTIFS(NetworkX!$D:$D, "*"&$Q2&"*")+COUNTIFS(rich!$D:$D, "*"&$Q2&"*")+COUNTIFS(tensorflow!$D:$D, "*"&$Q2&"*")+COUNTIFS(fastAPI!$D:$D, "*"&$Q2&"*")+COUNTIFS(httpx!$D:$D, "*"&$Q2&"*")+COUNTIFS(transformers!$D:$D, "*"&$Q2&"*")+COUNTIFS(django!$D:$D, "*"&$Q2&"*")+COUNTIFS(xgboost!$D:$D, "*"&$Q2&"*")+COUNTIFS(keras!$D:$D, "*"&$Q2&"*")+COUNTIFS(pytorch!$D:$D, "*"&$Q2&"*")+COUNTIFS(plotly.py!$D:$D, "*"&$Q2&"*")+COUNTIFS(dask!$D:$D, "*"&$Q2&"*")+COUNTIFS(polars!$D:$D, "*"&$Q2&"*")+COUNTIFS(loguru!$D:$D, "*"&$Q2&"*")+COUNTIFS(LightGBM!$D:$D, "*"&$Q2&"*")+COUNTIFS(sympy!$D:$D, "*"&$Q2&"*")+COUNTIFS(spaCy!$D:$D, "*"&$Q2&"*")+COUNTIFS(gensim!$D:$D, "*"&$Q2&"*")+COUNTIFS(jax!$D:$D, "*"&$Q2&"*")+COUNTIFS(aiohttp!$D:$D, "*"&$Q2&"*")+COUNTIFS(faker!$D:$D, "*"&$Q2&"*") -> 211 | S2: deprecat
D3: deprecates | E3: =COUNTIF(request!D:D, "*"&D3&"*")+COUNTIF(numpy!D:D, "*"&D3&"*")+COUNTIF(pandas!D:D, "*"&D3&"*")+COUNTIF(click!D:D, "*"&D3&"*")+COUNTIF(flask!D:D, "*"&D3&"*")+COUNTIF(pydantic!D:D, "*"&D3&"*")+COUNTIF(SciPy!D:D, "*"&D3&"*")+COUNTIF(pillow!D:D, "*"&D3&"*")+COUNTIF('scikit-learn'!D:D, "*"&D3&"*")+COUNTIF(matplotlib!D:D, "*"&D3&"*")+COUNTIF('redis-py'!D:D, "*"&D3&"*")+COUNTIF(tornado!D:D, "*"&D3&"*")+COUNTIF(NetworkX!D:D, "*"&D3&"*")+COUNTIF(rich!D:D, "*"&D3&"*")+COUNTIF(tensorflow!D:D, "*"&D3&"*")+COUNTIF(fastAPI!D:D, "*"&D3&"*")+COUNTIF(httpx!D:D, "*"&D3&"*")+COUNTIF(transformers!D:D, "*"&D3&"*")+COUNTIF(django!D:D, "*"&D3&"*")+COUNTIF(xgboost!D:D, "*"&D3&"*")+COUNTIF(keras!D:D, "*"&D3&"*")+COUNTIF(pytorch!D:D, "*"&D3&"*")+COUNTIF(plotly.py!D:D, "*"&D3&"*")+COUNTIF(dask!D:D, "*"&D3&"*")+COUNTIF(polars!D:D, "*"&D3&"*")+COUNTIF(loguru!D:D, "*"&D3&"*")+COUNTIF(LightGBM!D:D, "*"&D3&"*")+COUNTIF(sympy!D:D, "*"&D3&"*")+COUNTIF(spaCy!D:D, "*"&D3&"*")+COUNTIF(gensim!D:D, "*"&D3&"*")+COUNTIF(jax!D:D, "*"&D3&"*")+COUNTIF(aiohttp!D:D, "*"&D3&"*")+COUNTIF(faker!D:D, "*"&D3&"*") -> 1 | I3: longer | J3: =SUM(E11:E20) -> 10 | K3: =COUNTIF(request!D:D, "*"&I3&"*")+COUNTIF(numpy!D:D, "*"&I3&"*")+COUNTIF(pandas!D:D, "*"&I3&"*")+COUNTIF(click!D:D, "*"&I3&"*")+COUNTIF(flask!D:D, "*"&I3&"*")+COUNTIF(pydantic!D:D, "*"&I3&"*")+COUNTIF(SciPy!D:D, "*"&I3&"*")+COUNTIF(pillow!D:D, "*"&I3&"*")+COUNTIF('scikit-learn'!D:D, "*"&I3&"*")+COUNTIF(matplotlib!D:D, "*"&I3&"*")+COUNTIF('redis-py'!D:D, "*"&I3&"*")+COUNTIF(tornado!D:D, "*"&I3&"*")+COUNTIF(NetworkX!D:D, "*"&I3&"*")+COUNTIF(rich!D:D, "*"&I3&"*")+COUNTIF(tensorflow!D:D, "*"&I3&"*")+COUNTIF(fastAPI!D:D, "*"&I3&"*")+COUNTIF(httpx!D:D, "*"&I3&"*")+COUNTIF(transformers!D:D, "*"&I3&"*")+COUNTIF(django!D:D, "*"&I3&"*")+COUNTIF(xgboost!D:D, "*"&I3&"*")+COUNTIF(keras!D:D, "*"&I3&"*")+COUNTIF(pytorch!D:D, "*"&I3&"*")+COUNTIF(plotly.py!D:D, "*"&I3&"*")+COUNTIF(dask!D:D, "*"&I3&"*")+COUNTIF(polars!D:D, "*"&I3&"*")+COUNTIF(loguru!D:D, "*"&I3&"*")+COUNTIF(LightGBM!D:D, "*"&I3&"*")+COUNTIF(sympy!D:D, "*"&I3&"*")+COUNTIF(spaCy!D:D, "*"&I3&"*")+COUNTIF(gensim!D:D, "*"&I3&"*")+COUNTIF(jax!D:D, "*"&I3&"*")+COUNTIF(aiohttp!D:D, "*"&I3&"*")+COUNTIF(faker!D:D, "*"&I3&"*") -> 10 | L3: =K3/B$1 -> 0.026954178 | Q3: mov | R3: =COUNTIFS(request!$D:$D, "*"&$Q3&"*")+COUNTIFS(numpy!$D:$D, "*"&$Q3&"*")+COUNTIFS(pandas!$D:$D, "*"&$Q3&"*")+COUNTIFS(click!$D:$D, "*"&$Q3&"*")+COUNTIFS(flask!$D:$D, "*"&$Q3&"*")+COUNTIFS(pydantic!$D:$D, "*"&$Q3&"*")+COUNTIFS(SciPy!$D:$D, "*"&$Q3&"*")+COUNTIFS(pillow!$D:$D, "*"&$Q3&"*")+COUNTIFS('scikit-learn'!$D:$D, "*"&$Q3&"*")+COUNTIFS(matplotlib!$D:$D, "*"&$Q3&"*")+COUNTIFS('redis-py'!$D:$D, "*"&$Q3&"*")+COUNTIFS(tornado!$D:$D, "*"&$Q3&"*")+COUNTIFS(NetworkX!$D:$D, "*"&$Q3&"*")+COUNTIFS(rich!$D:$D, "*"&$Q3&"*")+COUNTIFS(tensorflow!$D:$D, "*"&$Q3&"*")+COUNTIFS(fastAPI!$D:$D, "*"&$Q3&"*")+COUNTIFS(httpx!$D:$D, "*"&$Q3&"*")+COUNTIFS(transformers!$D:$D, "*"&$Q3&"*")+COUNTIFS(django!$D:$D, "*"&$Q3&"*")+COUNTIFS(xgboost!$D:$D, "*"&$Q3&"*")+COUNTIFS(keras!$D:$D, "*"&$Q3&"*")+COUNTIFS(pytorch!$D:$D, "*"&$Q3&"*")+COUNTIFS(plotly.py!$D:$D, "*"&$Q3&"*")+COUNTIFS(dask!$D:$D, "*"&$Q3&"*")+COUNTIFS(polars!$D:$D, "*"&$Q3&"*")+COUNTIFS(loguru!$D:$D, "*"&$Q3&"*")+COUNTIFS(LightGBM!$D:$D, "*"&$Q3&"*")+COUNTIFS(sympy!$D:$D, "*"&$Q3&"*")+COUNTIFS(spaCy!$D:$D, "*"&$Q3&"*")+COUNTIFS(gensim!$D:$D, "*"&$Q3&"*")+COUNTIFS(jax!$D:$D, "*"&$Q3&"*")+COUNTIFS(aiohttp!$D:$D, "*"&$Q3&"*")+COUNTIFS(faker!$D:$D, "*"&$Q3&"*") -> 156 | S3: 119 | T3: deprecat+mov
D4: deprecated | E4: =COUNTIF(request!D:D, "*"&D4&"*")+COUNTIF(numpy!D:D, "*"&D4&"*")+COUNTIF(pandas!D:D, "*"&D4&"*")+COUNTIF(click!D:D, "*"&D4&"*")+COUNTIF(flask!D:D, "*"&D4&"*")+COUNTIF(pydantic!D:D, "*"&D4&"*")+COUNTIF(SciPy!D:D, "*"&D4&"*")+COUNTIF(pillow!D:D, "*"&D4&"*")+COUNTIF('scikit-learn'!D:D, "*"&D4&"*")+COUNTIF(matplotlib!D:D, "*"&D4&"*")+COUNTIF('redis-py'!D:D, "*"&D4&"*")+COUNTIF(tornado!D:D, "*"&D4&"*")+COUNTIF(NetworkX!D:D, "*"&D4&"*")+COUNTIF(rich!D:D, "*"&D4&"*")+COUNTIF(tensorflow!D:D, "*"&D4&"*")+COUNTIF(fastAPI!D:D, "*"&D4&"*")+COUNTIF(httpx!D:D, "*"&D4&"*")+COUNTIF(transformers!D:D, "*"&D4&"*")+COUNTIF(django!D:D, "*"&D4&"*")+COUNTIF(xgboost!D:D, "*"&D4&"*")+COUNTIF(keras!D:D, "*"&D4&"*")+COUNTIF(pytorch!D:D, "*"&D4&"*")+COUNTIF(plotly.py!D:D, "*"&D4&"*")+COUNTIF(dask!D:D, "*"&D4&"*")+COUNTIF(polars!D:D, "*"&D4&"*")+COUNTIF(loguru!D:D, "*"&D4&"*")+COUNTIF(LightGBM!D:D, "*"&D4&"*")+COUNTIF(sympy!D:D, "*"&D4&"*")+COUNTIF(spaCy!D:D, "*"&D4&"*")+COUNTIF(gensim!D:D, "*"&D4&"*")+COUNTIF(jax!D:D, "*"&D4&"*")+COUNTIF(aiohttp!D:D, "*"&D4&"*")+COUNTIF(faker!D:D, "*"&D4&"*") -> 187 | I4: delet | J4: =E21+E22+E23 -> 5 | K4: =COUNTIF(request!D:D, "*"&I4&"*")+COUNTIF(numpy!D:D, "*"&I4&"*")+COUNTIF(pandas!D:D, "*"&I4&"*")+COUNTIF(click!D:D, "*"&I4&"*")+COUNTIF(flask!D:D, "*"&I4&"*")+COUNTIF(pydantic!D:D, "*"&I4&"*")+COUNTIF(SciPy!D:D, "*"&I4&"*")+COUNTIF(pillow!D:D, "*"&I4&"*")+COUNTIF('scikit-learn'!D:D, "*"&I4&"*")+COUNTIF(matplotlib!D:D, "*"&I4&"*")+COUNTIF('redis-py'!D:D, "*"&I4&"*")+COUNTIF(tornado!D:D, "*"&I4&"*")+COUNTIF(NetworkX!D:D, "*"&I4&"*")+COUNTIF(rich!D:D, "*"&I4&"*")+COUNTIF(tensorflow!D:D, "*"&I4&"*")+COUNTIF(fastAPI!D:D, "*"&I4&"*")+COUNTIF(httpx!D:D, "*"&I4&"*")+COUNTIF(transformers!D:D, "*"&I4&"*")+COUNTIF(django!D:D, "*"&I4&"*")+COUNTIF(xgboost!D:D, "*"&I4&"*")+COUNTIF(keras!D:D, "*"&I4&"*")+COUNTIF(pytorch!D:D, "*"&I4&"*")+COUNTIF(plotly.py!D:D, "*"&I4&"*")+COUNTIF(dask!D:D, "*"&I4&"*")+COUNTIF(polars!D:D, "*"&I4&"*")+COUNTIF(loguru!D:D, "*"&I4&"*")+COUNTIF(LightGBM!D:D, "*"&I4&"*")+COUNTIF(sympy!D:D, "*"&I4&"*")+COUNTIF(spaCy!D:D, "*"&I4&"*")+COUNTIF(gensim!D:D, "*"&I4&"*")+COUNTIF(jax!D:D, "*"&I4&"*")+COUNTIF(aiohttp!D:D, "*"&I4&"*")+COUNTIF(faker!D:D, "*"&I4&"*") -> 3 | L4: =K4/B$1 -> 0.0080862534 | Q4: instead | R4: =COUNTIFS(request!$D:$D, "*"&$Q4&"*")+COUNTIFS(numpy!$D:$D, "*"&$Q4&"*")+COUNTIFS(pandas!$D:$D, "*"&$Q4&"*")+COUNTIFS(click!$D:$D, "*"&$Q4&"*")+COUNTIFS(flask!$D:$D, "*"&$Q4&"*")+COUNTIFS(pydantic!$D:$D, "*"&$Q4&"*")+COUNTIFS(SciPy!$D:$D, "*"&$Q4&"*")+COUNTIFS(pillow!$D:$D, "*"&$Q4&"*")+COUNTIFS('scikit-learn'!$D:$D, "*"&$Q4&"*")+COUNTIFS(matplotlib!$D:$D, "*"&$Q4&"*")+COUNTIFS('redis-py'!$D:$D, "*"&$Q4&"*")+COUNTIFS(tornado!$D:$D, "*"&$Q4&"*")+COUNTIFS(NetworkX!$D:$D, "*"&$Q4&"*")+COUNTIFS(rich!$D:$D, "*"&$Q4&"*")+COUNTIFS(tensorflow!$D:$D, "*"&$Q4&"*")+COUNTIFS(fastAPI!$D:$D, "*"&$Q4&"*")+COUNTIFS(httpx!$D:$D, "*"&$Q4&"*")+COUNTIFS(transformers!$D:$D, "*"&$Q4&"*")+COUNTIFS(django!$D:$D, "*"&$Q4&"*")+COUNTIFS(xgboost!$D:$D, "*"&$Q4&"*")+COUNTIFS(keras!$D:$D, "*"&$Q4&"*")+COUNTIFS(pytorch!$D:$D, "*"&$Q4&"*")+COUNTIFS(plotly.py!$D:$D, "*"&$Q4&"*")+COUNTIFS(dask!$D:$D, "*"&$Q4&"*")+COUNTIFS(polars!$D:$D, "*"&$Q4&"*")+COUNTIFS(loguru!$D:$D, "*"&$Q4&"*")+COUNTIFS(LightGBM!$D:$D, "*"&$Q4&"*")+COUNTIFS(sympy!$D:$D, "*"&$Q4&"*")+COUNTIFS(spaCy!$D:$D, "*"&$Q4&"*")+COUNTIFS(gensim!$D:$D, "*"&$Q4&"*")+COUNTIFS(jax!$D:$D, "*"&$Q4&"*")+COUNTIFS(aiohttp!$D:$D, "*"&$Q4&"*")+COUNTIFS(faker!$D:$D, "*"&$Q4&"*") -> 96 | S4: =T4/R4 -> 0.072916667 | T4: 7
D5: deprecation | E5: =COUNTIF(request!D:D, "*"&D5&"*")+COUNTIF(numpy!D:D, "*"&D5&"*")+COUNTIF(pandas!D:D, "*"&D5&"*")+COUNTIF(click!D:D, "*"&D5&"*")+COUNTIF(flask!D:D, "*"&D5&"*")+COUNTIF(pydantic!D:D, "*"&D5&"*")+COUNTIF(SciPy!D:D, "*"&D5&"*")+COUNTIF(pillow!D:D, "*"&D5&"*")+COUNTIF('scikit-learn'!D:D, "*"&D5&"*")+COUNTIF(matplotlib!D:D, "*"&D5&"*")+COUNTIF('redis-py'!D:D, "*"&D5&"*")+COUNTIF(tornado!D:D, "*"&D5&"*")+COUNTIF(NetworkX!D:D, "*"&D5&"*")+COUNTIF(rich!D:D, "*"&D5&"*")+COUNTIF(tensorflow!D:D, "*"&D5&"*")+COUNTIF(fastAPI!D:D, "*"&D5&"*")+COUNTIF(httpx!D:D, "*"&D5&"*")+COUNTIF(transformers!D:D, "*"&D5&"*")+COUNTIF(django!D:D, "*"&D5&"*")+COUNTIF(xgboost!D:D, "*"&D5&"*")+COUNTIF(keras!D:D, "*"&D5&"*")+COUNTIF(pytorch!D:D, "*"&D5&"*")+COUNTIF(plotly.py!D:D, "*"&D5&"*")+COUNTIF(dask!D:D, "*"&D5&"*")+COUNTIF(polars!D:D, "*"&D5&"*")+COUNTIF(loguru!D:D, "*"&D5&"*")+COUNTIF(LightGBM!D:D, "*"&D5&"*")+COUNTIF(sympy!D:D, "*"&D5&"*")+COUNTIF(spaCy!D:D, "*"&D5&"*")+COUNTIF(gensim!D:D, "*"&D5&"*")+COUNTIF(jax!D:D, "*"&D5&"*")+COUNTIF(aiohttp!D:D, "*"&D5&"*")+COUNTIF(faker!D:D, "*"&D5&"*") -> 15 | F5: =E5-E6 -> 12 | I5: discourag | J5: =E24 -> 3 | K5: =COUNTIF(request!D:D, "*"&I5&"*")+COUNTIF(numpy!D:D, "*"&I5&"*")+COUNTIF(pandas!D:D, "*"&I5&"*")+COUNTIF(click!D:D, "*"&I5&"*")+COUNTIF(flask!D:D, "*"&I5&"*")+COUNTIF(pydantic!D:D, "*"&I5&"*")+COUNTIF(SciPy!D:D, "*"&I5&"*")+COUNTIF(pillow!D:D, "*"&I5&"*")+COUNTIF('scikit-learn'!D:D, "*"&I5&"*")+COUNTIF(matplotlib!D:D, "*"&I5&"*")+COUNTIF('redis-py'!D:D, "*"&I5&"*")+COUNTIF(tornado!D:D, "*"&I5&"*")+COUNTIF(NetworkX!D:D, "*"&I5&"*")+COUNTIF(rich!D:D, "*"&I5&"*")+COUNTIF(tensorflow!D:D, "*"&I5&"*")+COUNTIF(fastAPI!D:D, "*"&I5&"*")+COUNTIF(httpx!D:D, "*"&I5&"*")+COUNTIF(transformers!D:D, "*"&I5&"*")+COUNTIF(django!D:D, "*"&I5&"*")+COUNTIF(xgboost!D:D, "*"&I5&"*")+COUNTIF(keras!D:D, "*"&I5&"*")+COUNTIF(pytorch!D:D, "*"&I5&"*")+COUNTIF(plotly.py!D:D, "*"&I5&"*")+COUNTIF(dask!D:D, "*"&I5&"*")+COUNTIF(polars!D:D, "*"&I5&"*")+COUNTIF(loguru!D:D, "*"&I5&"*")+COUNTIF(LightGBM!D:D, "*"&I5&"*")+COUNTIF(sympy!D:D, "*"&I5&"*")+COUNTIF(spaCy!D:D, "*"&I5&"*")+COUNTIF(gensim!D:D, "*"&I5&"*")+COUNTIF(jax!D:D, "*"&I5&"*")+COUNTIF(aiohttp!D:D, "*"&I5&"*")+COUNTIF(faker!D:D, "*"&I5&"*") -> 3 | L5: =K5/B$1 -> 0.0080862534 | Q5: replac | R5: =COUNTIFS(request!$D:$D, "*"&$Q5&"*")+COUNTIFS(numpy!$D:$D, "*"&$Q5&"*")+COUNTIFS(pandas!$D:$D, "*"&$Q5&"*")+COUNTIFS(click!$D:$D, "*"&$Q5&"*")+COUNTIFS(flask!$D:$D, "*"&$Q5&"*")+COUNTIFS(pydantic!$D:$D, "*"&$Q5&"*")+COUNTIFS(SciPy!$D:$D, "*"&$Q5&"*")+COUNTIFS(pillow!$D:$D, "*"&$Q5&"*")+COUNTIFS('scikit-learn'!$D:$D, "*"&$Q5&"*")+COUNTIFS(matplotlib!$D:$D, "*"&$Q5&"*")+COUNTIFS('redis-py'!$D:$D, "*"&$Q5&"*")+COUNTIFS(tornado!$D:$D, "*"&$Q5&"*")+COUNTIFS(NetworkX!$D:$D, "*"&$Q5&"*")+COUNTIFS(rich!$D:$D, "*"&$Q5&"*")+COUNTIFS(tensorflow!$D:$D, "*"&$Q5&"*")+COUNTIFS(fastAPI!$D:$D, "*"&$Q5&"*")+COUNTIFS(httpx!$D:$D, "*"&$Q5&"*")+COUNTIFS(transformers!$D:$D, "*"&$Q5&"*")+COUNTIFS(django!$D:$D, "*"&$Q5&"*")+COUNTIFS(xgboost!$D:$D, "*"&$Q5&"*")+COUNTIFS(keras!$D:$D, "*"&$Q5&"*")+COUNTIFS(pytorch!$D:$D, "*"&$Q5&"*")+COUNTIFS(plotly.py!$D:$D, "*"&$Q5&"*")+COUNTIFS(dask!$D:$D, "*"&$Q5&"*")+COUNTIFS(polars!$D:$D, "*"&$Q5&"*")+COUNTIFS(loguru!$D:$D, "*"&$Q5&"*")+COUNTIFS(LightGBM!$D:$D, "*"&$Q5&"*")+COUNTIFS(sympy!$D:$D, "*"&$Q5&"*")+COUNTIFS(spaCy!$D:$D, "*"&$Q5&"*")+COUNTIFS(gensim!$D:$D, "*"&$Q5&"*")+COUNTIFS(jax!$D:$D, "*"&$Q5&"*")+COUNTIFS(aiohttp!$D:$D, "*"&$Q5&"*")+COUNTIFS(faker!$D:$D, "*"&$Q5&"*") -> 27 | S5: =T5/R5 -> 0.22222222 | T5: 6 | U5: deprecat+mov+replac
